# name: try 
# key: try 
# --

try {
    $1
} catch (const std::exception &e) {
  std::cerr << e.what() << std::endl;

}
